

~/dl_toolbox/docs/examples/unet_semcity_torch.py 

Traceback (most recent call last):
  File "unet_semcity_torch.py", line 4, in <module>
    from dl_toolbox.torch_datasets import InriaDS
ModuleNotFoundError: No module named 'dl_toolbox'

Comment : does not recognize the dl_toolbox module
fixe when moved to ~/DL/dl_toolbox/unet_semcity_torch.py






~/DL/dl_toolbox/unet_semcity_torch.py
~/DL/dl_toolbox/dl_toolbox/torch_datasets/InriaDS.py

Traceback (most recent call last):
  File "unet_semcity_torch.py", line 195, in <module>
    main()
  File "unet_semcity_torch.py", line 46, in main
    dataset1 = InriaDS(
TypeError: 'module' object is not callable

Comment : module object not callable when InriaDS is not moved





Traceback (most recent call last):
  File "unet_semcity_torch.py", line 4, in <module>
    from dl_toolbox.torch_datasets import InriaDS
  File "/d/maboum/DL/dl_toolbox/dl_toolbox/torch_datasets/InriaDS.py", line 10, in <module>
    from dl_toolbox.augmentations import get_transforms
ImportError: cannot import name 'get_transforms' from 'dl_toolbox.augmentations' (/d/maboum/DL/dl_toolbox/dl_toolbox/augmentations/__init__.py)

Comment: trouble importing get_transforms from dl_toolbox.augmentations changing location to ~/DL/dl_toolbox/

Traceback (most recent call last):
  File "unet_semcity_torch.py", line 4, in <module>
    import InriaDS
  File "/d/maboum/DL/dl_toolbox/InriaDS.py", line 10, in <module>
    from dl_toolbox.augmentations import get_transforms
ImportError: cannot import name 'get_transforms' from 'dl_toolbox.augmentations' (/d/maboum/DL/dl_toolbox/dl_toolbox/augmentations/__init__.py)


Comment: Sort of fixed but may come back to bite me in the *** #from dl_toolbox.augmentations import get_transforms in ~/DL/dl_toolbox/InriaDS.py

~/DL/dl_toolbox/unet_semcity_torch.py
~/DL/dl_toolbox/InriaDS.py

Traceback (most recent call last):
  File "unet_semcity_torch.py", line 12, in <module>
    import tabulate
ModuleNotFoundError: No module named 'tabulate'

Comment : need to install tabulate 

python3 unet_semcity_torch.py [--num_classes 2 --in_channels 3 --encoder resnet34 --initial_lr 0.001 --final_lr 0.0001 --lr_milestones [30,80] --data_path /data/INRIA/AerialImageDataset/train --crop_size 256]
usage: unet_semcity_torch.py [-h] [--output_dir OUTPUT_DIR]
                             [--num_classes NUM_CLASSES] [--train_with_void]
                             [--eval_with_void] [--in_channels IN_CHANNELS]
                             [--pretrained] [--encoder ENCODER]
                             [--initial_lr INITIAL_LR] [--final_lr FINAL_LR]
                             [--lr_milestones LR_MILESTONES LR_MILESTONES]
                             [--data_path DATA_PATH] [--epoch_len EPOCH_LEN]
                             [--sup_batch_size SUP_BATCH_SIZE]
                             [--crop_size CROP_SIZE] [--workers WORKERS]
                             [--img_aug IMG_AUG] [--max_epochs MAX_EPOCHS]
                             [--seed S]
unet_semcity_torch.py: error: argument --lr_milestones: expected 2 arguments

Comment --lr_milestones : 30 80

Traceback (most recent call last):
  File "unet_semcity_torch.py", line 195, in <module>
    main()
  File "unet_semcity_torch.py", line 46, in main
    dataset1 = InriaDS(
TypeError: 'module' object is not callable

Comment:  error caused by l4 import InriaDS changed it to from InriaDS import InriaDS

Traceback (most recent call last):
  File "unet_semcity_torch.py", line 195, in <module>
    main()
  File "unet_semcity_torch.py", line 46, in main
    dataset1 = InriaDS(
  File "/d/maboum/DL/dl_toolbox/InriaDS.py", line 35, in __init__
    self.img_aug = get_transforms(img_aug)
NameError: name 'get_transforms' is not defined


Comment : Well here it is...
#from dl_toolbox.augmentations import get_transforms replace with line below
from dl_toolbox.torch_datasets.utils import *

Traceback (most recent call last):
  File "/d/maboum/.local/lib/python3.8/site-packages/torch/utils/data/_utils/worker.py", line 302, in _worker_loop
    data = fetcher.fetch(index)
  File "/d/maboum/.local/lib/python3.8/site-packages/torch/utils/data/_utils/fetch.py", line 49, in fetch
    data = [self.dataset[idx] for idx in possibly_batched_index]
  File "/d/maboum/.local/lib/python3.8/site-packages/torch/utils/data/_utils/fetch.py", line 49, in <listcomp>
    data = [self.dataset[idx] for idx in possibly_batched_index]
  File "/d/maboum/.local/lib/python3.8/site-packages/torch/utils/data/dataset.py", line 235, in __getitem__
    return self.datasets[dataset_idx][sample_idx]
  File "/d/maboum/DL/dl_toolbox/InriaDS.py", line 65, in __getitem__
    with rasterio.open(self.image_path) as image_file:
  File "/d/maboum/.local/lib/python3.8/site-packages/rasterio/env.py", line 442, in wrapper
    return f(*args, **kwds)
  File "/d/maboum/.local/lib/python3.8/site-packages/rasterio/__init__.py", line 277, in open
    dataset = DatasetReader(path, driver=driver, sharing=sharing, **kwargs)
  File "rasterio/_base.pyx", line 304, in rasterio._base.DatasetBase.__init__
rasterio.errors.RasterioIOError: ./data/INRIA/AerialImageDataset/train/images/austin11.tif: No such file or directory


comment : use '//' for paths!!



